Workbook

Sheet REPORTE
B2: REPORTE DE ESTATUS SEMANAL
E5: PROYECTO: | H5: CASETA PASADENA | L5: SEMANA No.
E6: UBICACIÓN: | H6: HERMOSILLO, SONORA | L6: 08
E7: GERENCIA DE PROYECTO | H7: METTA GROUP
E8: FECHA DEL PERIODO: | H8: SEMANA 08 - DEL 01 AL 06 DE JUNIO
B10: ACTIVIDADES
B11: ACTIVIDADES REALIZADAS ESTA SEMANA - 08 | H11: ACTIVIDADES PROGRAMADAS PROXIMA SEMANA - 09
B13: Colocación de Muro de Block | H13: Continuación de Muro de Block hasta altura de cubierta
B14: Colado de castillos | H14: Continuación de colado de castillos
B15: Inicio de Cimentación Ciclopea | H15: Block dala (cerramiento)
B16: Habilitado y maniobra para instalación de Polines 12" | H16: Colado de Cimentación Ciclopea
H17: Suministro y habilitado de PTRs
B33: PROBLEMAS QUE PUEDEN VOLVERSE CRÍTICOS | H33: ESTATUS | J33: FECHA LÍMITE | L33: RESPONSABLE
B35: Apegarse al programa de obra y de suministros | H35: En proceso | J35: -- | L35: Todos
B44: CONCEPTO | G44: PROGRAM. | H44: REAL | I44: VARIACION | J44: PROGRAMADO VS REAL
B46: =+AVANCES!B6 -> CIMENTACION | G46: =+AVANCES!E6 -> 1 | H46: =+AVANCES!F6 -> 0.95038869 | I46: =+H46-G46 -> -0.049611311
B47: =+AVANCES!B19 -> ALBAÑILERIA | G47: =+AVANCES!E19 -> 0.89989875 | H47: =+AVANCES!F19 -> 0.66180273 | I47: =+H47-G47 -> -0.23809602
B48: =+AVANCES!B23 -> PLAFONES | G48: =+AVANCES!E23 -> 0 | H48: =+AVANCES!F23 -> 0 | I48: =+H48-G48 -> 0
B49: =+AVANCES!B27 -> ACABADOS | G49: =+AVANCES!E27 -> 0 | H49: =+AVANCES!F27 -> 0 | I49: =+H49-G49 -> 0
B50: =+AVANCES!B35 -> ESTRUCTURA TECHUMBRE | G50: =+AVANCES!E35 -> 0.83618669 | H50: =+AVANCES!F35 -> 0.7929725 | I50: =+H50-G50 -> -0.043214194
B51: =+AVANCES!B45 -> HERRERIAS | G51: =+AVANCES!E45 -> 0 | H51: =+AVANCES!F45 -> 0 | I51: =+H51-G51 -> 0
B52: =+AVANCES!B49 -> CARPINTERIA Y CANCELERIA | G52: =+AVANCES!E49 -> 0 | H52: =+AVANCES!F49 -> 0 | I52: =+H52-G52 -> 0
B53: =+AVANCES!B54 -> INSTALACIONES HIDRÁULICAS | G53: =+AVANCES!E54 -> 0 | H53: =+AVANCES!F54 -> 0 | I53: =+H53-G53 -> 0
B54: =+AVANCES!B76 -> INSTALACIONES ELECTRICAS | G54: =+AVANCES!E76 -> 0.76144991 | H54: =+AVANCES!F76 -> 0.65722009 | I54: =+H54-G54 -> -0.10422982
B55: =+AVANCES!B96 -> SISTEMA DE AIRES ACONDICIONADOS | G55: =+AVANCES!E96 -> 0.046028247 | H55: =+AVANCES!F96 -> 0.011317308 | I55: =+H55-G55 -> -0.034710939
B56: =+AVANCES!B100 -> CONTROL DE ACCESO | G56: =+AVANCES!E100 -> 0 | H56: =+AVANCES!F100 -> 0 | I56: =+H56-G56 -> 0
B57: =+AVANCES!B112 -> LETRERO | G57: =+AVANCES!E112 -> 0 | H57: =+AVANCES!F112 -> 0 | I57: =+H57-G57 -> 0
B60: REPORTE DE ESTATUS SEMANAL
E63: PROYECTO: | H63: CASETA PASADENA | L63: SEMANA No.
E64: UBICACIÓN: | H64: HERMOSILLO, SONORA | L64: 08
E65: GERENCIA DE PROYECTO | H65: METTA GROUP
E66: FECHA DEL PERIODO: | H66: SEMANA 08 - DEL 01 AL 06 DE JUNIO
B68: PROGRAMA MAESTRO
C95: AVANCE PROGRAMADO SEMANA - 09 | G95: AVANCE FÍSICO - FINANCIERO SEMANA - 09 | K95: VARIACION
C96: =+AVANCES!G4 -> 629971.44 | G96: =+AVANCES!H4 -> 560216.78 | K96: =+G96-C96 -> -69754.666
C97: =+AVANCES!E4 -> 0.35489489 | G97: =+AVANCES!F4 -> 0.31559854 | K97: =+G97-C97 -> -0.039296343
P100: AVANCE PROGRAMADO
P101: =+REPORTE!C97 -> 0.35489489 | Q101: =100%-P101 -> 0.64510511
P102: AVANCE PROG. | Q102: POR EJECUTAR
P105: AVANCE FÍSICO REAL
...

Sheet AVANCES
E2: % PROGRAMADO | F2: % REAL | G2: $ PROGRAMADO | H2: $ REAL
B4: CASETA PASADENA | C4: =+C6+C19+C23+C27+C35+C45+C76+C100+C112+C49+C96+C54 -> 1775093 | E4: =+G4/C4 -> 0.35489489 | F4: =+H4/C4 -> 0.31559854 | G4: =+G6+G19+G23+G27+G35+G45+G76+G100+G112+G49+G96+G54 -> 629971.44 | H4: =+H6+H19+H23+H27+H35+H45+H76+H100+H112+H49+H96+H54 -> 560216.78
B6: CIMENTACION | C6: 136849.72 | E6: =+G6/C6 -> 1 | F6: =+H6/C6 -> 0.95038869 | G6: =SUM(G7:G18) -> 136849.72 | H6: =SUM(H7:H18) -> 130060.43
B7: Trazo y nivelación | C7: 610.38 | E7: 1 | F7: 1 | G7: =+E7*C7 -> 610.38 | H7: =+F7*C7 -> 610.38
B8: Excavación por medios manuales de terreno tipo II | C8: 2041.22 | E8: 1 | F8: 1 | G8: =+E8*C8 -> 2041.22 | H8: =+F8*C8 -> 2041.22
B9: Plantilla de concreto simple fc=100 kg/cm2, e=5 cm | C9: 1243.92 | E9: 1 | F9: 1 | G9: =+E9*C9 -> 1243.92 | H9: =+F9*C9 -> 1243.92
B10: Cimentación de concreto ciclopeo fc=200 kg/cm2 | C10: 7543.66 | E10: 1 | F10: 0.1 | G10: =+E10*C10 -> 7543.66 | H10: =+F10*C10 -> 754.366
B11: Zapata ZA-4, 1.00x1.00x0.25 m, f'c=250 kg/cm2 | C11: 32039.22 | E11: 1 | F11: 1 | G11: =+E11*C11 -> 32039.22 | H11: =+F11*C11 -> 32039.22
B12: Dado D-1, 0.40x0.40x0.50 m, f'c=250 kg/cm2 | C12: 25502.76 | E12: 1 | F12: 1 | G12: =+E12*C12 -> 25502.76 | H12: =+F12*C12 -> 25502.76
B13: Anclas AN-1, redondo 3/4 roscado con placa 35x35 cm | C13: 13910.22 | E13: 1 | F13: 1 | G13: =+E13*C13 -> 13910.22 | H13: =+F13*C13 -> 13910.22
B14: Dentellón DE-1, 20x30 cm, f'c=250 kg/cm2 | C14: 30086.75 | E14: 1 | F14: 1 | G14: =+E14*C14 -> 30086.75 | H14: =+F14*C14 -> 30086.75
B15: Relleno compactado al 95% PVSM, capas de 20 cm | C15: 2281.08 | E15: 1 | F15: 1 | G15: =+E15*C15 -> 2281.08 | H15: =+F15*C15 -> 2281.08
B16: Carga y acarreo de material sobrante a tiro | C16: 271.99 | E16: 1 | F16: 1 | G16: =+E16*C16 -> 271.99 | H16: =+F16*C16 -> 271.99
B17: Preparacion de Losa de cimentación | C17: 8527.41 | E17: 1 | F17: 1 | G17: =+E17*C17 -> 8527.41 | H17: =+F17*C17 -> 8527.41
B18: Colado de Losa de cimentación | C18: 12791.11 | E18: 1 | F18: 1 | G18: =+E18*C18 -> 12791.11 | H18: =+F18*C18 -> 12791.11
B19: ALBAÑILERIA | C19: 141737.89 | E19: =+G19/C19 -> 0.89989875 | F19: =+H19/C19 -> 0.66180273 | G19: =SUM(G20:G22) -> 127549.75 | H19: =SUM(H20:H22) -> 93802.523
B20: Muro de block hueco 15x20x40 cm, mortero 1:3 | C20: 109244.69 | E20: 1 | F20: 0.8 | G20: =+E20*C20 -> 109244.69 | H20: =+F20*C20 -> 87395.752
B21: Muro de tablaroca estándar 1/2 a dos caras | C21: 14188.14 | E21: 0 | F21: 0 | G21: =+E21*C21 -> 0 | H21: =+F21*C21 -> 0
B22: Cadena de desplante/cerramiento 14x20 cm | C22: 18305.06 | E22: 1 | F22: 0.35 | G22: =+E22*C22 -> 18305.06 | H22: =+F22*C22 -> 6406.771
B23: PLAFONES | C23: 140350.78 | E23: =+G23/C23 -> 0 | F23: =+H23/C23 -> 0 | G23: =SUM(G24:G26) -> 0 | H23: =SUM(H24:H26) -> 0
B24: Cubierta tablacemento Durock 1/2 con triplay 1/2 | C24: 73737.34 | E24: 0 | F24: 0 | G24: =+E24*C24 -> 0 | H24: =+F24*C24 -> 0
B25: Impermeabilizante APP poliéster gravilla 4.5 mm | C25: 24280.18 | E25: 0 | F25: 0 | G25: =+E25*C25 -> 0 | H25: =+F25*C25 -> 0
B26: Plafón de tablaroca yeso 1/2 sobre bastidor de aluminio | C26: 42333.26 | E26: 0 | F26: 0 | G26: =+E26*C26 -> 0 | H26: =+F26*C26 -> 0
B27: ACABADOS | C27: 199033.2 | E27: =+G27/C27 -> 0 | F27: =+H27/C27 -> 0 | G27: =SUM(G28:G34) -> 0 | H27: =SUM(H28:H34) -> 0
B28: Recubrimiento de muro con piedra, acabado plaqueado | C28: 149624.02 | E28: 0 | F28: 0 | G28: =+E28*C28 -> 0 | H28: =+F28*C28 -> 0
B29: Zarpeo y afine fino, mortero cemento-arena 1:4 | C29: 4606.15 | E29: 0 | F29: 0 | G29: =+E29*C29 -> 0 | H29: =+F29*C29 -> 0
B30: Enjarre grueso interior, e=1.5-2.0 cm, mortero 1:3 | C30: 12572.62 | E30: 0 | F30: 0 | G30: =+E30*C30 -> 0 | H30: =+F30*C30 -> 0
B31: Pintura vinílica interior a dos manos | C31: 9035.06 | E31: 0 | F31: 0 | G31: =+E31*C31 -> 0 | H31: =+F31*C31 -> 0
B32: Loseta cerámica Metallic Gold 60x360 cm en piso | C32: 17496.64 | E32: 0 | F32: 0 | G32: =+E32*C32 -> 0 | H32: =+F32*C32 -> 0
B33: Zóclo cerámica Metallic Gold 10x60 cm | C33: 4186.91 | E33: 0 | F33: 0 | G33: =+E33*C33 -> 0 | H33: =+F33*C33 -> 0
B34: Resaltes de concreto fc=200 kg/cm2, e=10 cm, 30x30 cm | C34: 1511.8 | E34: 0 | F34: 0 | G34: =+E34*C34 -> 0 | H34: =+F34*C34 -> 0
B35: ESTRUCTURA TECHUMBRE | C35: 262079.24 | E35: =+G35/C35 -> 0.83618669 | F35: =+H35/C35 -> 0.7929725 | G35: =SUM(G36:G44) -> 219147.17 | H35: =SUM(H36:H44) -> 207821.63
B36: Anclas de redondo liso 3/4, L=0.75 m, roscas y tuercas | C36: 17171.04 | E36: 1 | F36: 1 | G36: =+E36*C36 -> 17171.04 | H36: =+F36*C36 -> 17171.04
B37: Placa base para columnas 5/8 8 cartabones | C37: 11102.69 | E37: 1 | F37: 1 | G37: =+E37*C37 -> 11102.69 | H37: =+F37*C37 -> 11102.69
B38: Columna metálica CM-2, PTR 6x6x3/16 | C38: 104227.7 | E38: 1 | F38: 1 | G38: =+E38*C38 -> 104227.7 | H38: =+F38*C38 -> 104227.7
B39: Placa superior de columnas 3/8 A-36, 0.10x0.10 m | C39: 15242.86 | E39: 1 | F39: 1 | G39: =+E39*C39 -> 15242.86 | H39: =+F39*C39 -> 15242.86
B40: Largueros de polín doble 12, 2x12MT-14 | C40: 45613.87 | E40: 0.88 | F40: 1 | G40: =+E40*C40 -> 40140.206 | H40: =+F40*C40 -> 45613.87
B41: Largueros de polín sencillo 12, 1x12MT-14 | C41: 28926.94 | E41: 0.88 | F41: 0.5 | G41: =+E41*C41 -> 25455.707 | H41: =+F41*C41 -> 14463.47
B42: Largueros de polín sencillo 6, 1x6MT-14 | C42: 17596.88 | E42: 0.33 | F42: 0 | G42: =+E42*C42 -> 5806.9704 | H42: =+F42*C42 -> 0
B43: Ángulos de conexión polín-polín 2x2x1/4 A-36 | C43: 4240.61 | E43: 0 | F43: 0 | G43: =+E43*C43 -> 0 | H43: =+F43*C43 -> 0
...

Sheet CURVA S BASE
B1: INICIO | C1: SEM 1 | D1: SEM 2 | E1: SEM 3 | F1: SEM 4 | G1: SEM 5 | H1: SEM 6 | I1: SEM 7 | J1: SEM 8 | K1: SEM 9 | L1: SEM 10 | M1: SEM 11 | N1: SEM 12 | O1: SEM 13 | P1: SEM 14 | Q1: SEM 15 | R1: SEM 16 | S1: SEM 17 | T1: SEM 18
A3: SEMANAL PROGRAMADO | B3: 0 | C3: 1835.11 | D3: 23757.7 | E3: 154246.94 | F3: 85184.14 | G3: 83768.58 | H3: 102741.42 | I3: 87016.89 | J3: 91109.82 | K3: 30841.47 | L3: 39294.54 | M3: 90611.57 | N3: 98396.85 | O3: 95064.82 | P3: 71973 | Q3: 153453.71 | R3: 313963.18 | S3: 224527.26 | T3: 27306.03
A4: ACUMULADO PROGRAMADO | B4: 0 | C4: =+B4+C3 -> 1835.11 | D4: =+C4+D3 -> 25592.81 | E4: =+D4+E3 -> 179839.75 | F4: =+E4+F3 -> 265023.89 | G4: =+F4+G3 -> 348792.47 | H4: =+G4+H3 -> 451533.89 | I4: =+H4+I3 -> 538550.78 | J4: =+I4+J3 -> 629660.6 | ... T4: =+S4+T3 -> 1775093
A8: SEMANAL REAL | B8: 0 | C8: =+C9-B9 -> 1835.11 | D8: =+D9-C9 -> 23757.7 | E8: =+E9-D9 -> 42450 | F8: =+F9-E9 -> 117382.69 | G8: =+G9-F9 -> 101625 | H8: =+H9-G9 -> 85000 | I8: =+I9-H9 -> 115658.81 | J8: =+J9-I9 -> 72507.469
A9: ACUMULADO REAL | B9: 0 | C9: 1835.11 | D9: 25592.81 | E9: =+D9+42450 -> 68042.81 | F9: 185425.5 | G9: =+F9+101625 -> 287050.5 | H9: =+G9+85000 -> 372050.5 | I9: =507709.31-20000 -> 487709.31 | J9: =+AVANCES!H4 -> 560216.78
